<sdf version='1.12'>
  <model name='go2'>
    <link name='base'>
      <inertial>
        <pose>0.020076415498763388 -1.1917583649194879e-19 -0.0051027873042044517 0 0 0</pose>
        <mass>7.2780000000000022</mass>
        <inertia>
          <ixx>0.025815203465732739</ixx>
          <ixy>0.00012166</ixy>
          <ixz>0.0015233596262671919</ixz>
          <iyy>0.1030543124481243</iyy>
          <iyz>-3.1199999999999993e-05</iyz>
          <izz>0.1127455974823915</izz>
        </inertia>
      </inertial>
      <collision name='base_fixed_joint_lump__trunk_collision'>
        <pose>0 0 0 0 0 0</pose>
        <geometry>
          <box>
            <size>0.37619999999999998 0.0935 0.114</size>
          </box>
        </geometry>
        <surface>
          <contact>
            <ode>
              <kp>1000000</kp>
              <kd>1</kd>
            </ode>
          </contact>
          <friction>
            <ode>
              <mu>0.20000000000000001</mu>
              <mu2>0.20000000000000001</mu2>
            </ode>
          </friction>
        </surface>
      </collision>
      <collision name='base_fixed_joint_lump__imu_link_collision_1'>
        <pose>0 0 0 0 0 0</pose>
        <geometry>
          <box>
            <size>0.001 0.001 0.001</size>
          </box>
        </geometry>
        <surface>
          <contact>
            <ode/>
          </contact>
          <friction>
            <ode>
              <mu>0.20000000000000001</mu>
              <mu2>0.20000000000000001</mu2>
            </ode>
          </friction>
        </surface>
      </collision>
      <visual name='base_visual'>
        <pose>0 0 0 0 0 0</pose>
        <geometry>
          <box>
            <size>0.001 0.001 0.001</size>
          </box>
        </geometry>
      </visual>
      <visual name='base_fixed_joint_lump__trunk_visual_1'>
        <pose>0 0 0 0 0 0</pose>
        <geometry>
          <mesh>
            <scale>1 1 1</scale>
            <uri>meshes/trunk.dae</uri>
          </mesh>
        </geometry>
      </visual>
      <visual name='base_fixed_joint_lump__FL_hip_rotor_visual_2'>
        <pose>0.11215 0.04675 0 0 1.5707963267948966 0</pose>
        <geometry>
          <cylinder>
            <length>0.02</length>
            <radius>0.035000000000000003</radius>
          </cylinder>
        </geometry>
        <material>
          <diffuse>0 1 0 1</diffuse>
          <ambient>0 1 0 1</ambient>
        </material>
      </visual>
      <visual name='base_fixed_joint_lump__FR_hip_rotor_visual_3'>
        <pose>0.11215 -0.04675 0 0 1.5707963267948966 0</pose>
        <geometry>
          <cylinder>
            <length>0.02</length>
            <radius>0.035000000000000003</radius>
          </cylinder>
        </geometry>
        <material>
          <diffuse>0 1 0 1</diffuse>
          <ambient>0 1 0 1</ambient>
        </material>
      </visual>
      <visual name='base_fixed_joint_lump__RL_hip_rotor_visual_4'>
        <pose>-0.11215 0.04675 0 0 1.5707963267948966 0</pose>
        <geometry>
          <cylinder>
            <length>0.02</length>
            <radius>0.035000000000000003</radius>
          </cylinder>
        </geometry>
        <material>
          <diffuse>0 1 0 1</diffuse>
          <ambient>0 1 0 1</ambient>
        </material>
      </visual>
      <visual name='base_fixed_joint_lump__RR_hip_rotor_visual_5'>
        <pose>-0.11215 -0.04675 0 0 1.5707963267948966 0</pose>
        <geometry>
          <cylinder>
            <length>0.02</length>
            <radius>0.035000000000000003</radius>
          </cylinder>
        </geometry>
        <material>
          <diffuse>0 1 0 1</diffuse>
          <ambient>0 1 0 1</ambient>
        </material>
      </visual>
      <visual name='base_fixed_joint_lump__imu_link_visual_6'>
        <pose>0 0 0 0 0 0</pose>
        <geometry>
          <box>
            <size>0.001 0.001 0.001</size>
          </box>
        </geometry>
      </visual>
      <gravity>true</gravity>
      <gravity>true</gravity>
      <sensor name="imu_sensor" type="imu">
          <always_on>1</always_on>
          <update_rate>200</update_rate>
          <visualize>true</visualize>
          <topic>imu</topic>
      </sensor>
    </link>
    <joint name='FL_hip_joint' type='revolute'>
      <pose relative_to='base'>0.19339999999999999 0.0465 0 0 0 0</pose>
      <parent>base</parent>
      <child>FL_hip</child>
      <axis>
        <xyz>1 0 0</xyz>
        <limit>
          <lower>-1.0471999999999999</lower>
          <upper>1.0471999999999999</upper>
          <effort>23.699999999999999</effort>
          <velocity>30.100000000000001</velocity>
        </limit>
        <dynamics>
          <damping>0</damping>
          <friction>0</friction>
          <spring_reference>0</spring_reference>
          <spring_stiffness>0</spring_stiffness>
        </dynamics>
      </axis>
    </joint>
    <link name='FL_hip'>
      <pose relative_to='FL_hip_joint'>0 0 0 0 0 0</pose>
      <inertial>
        <pose>-0.0047734028683181226 0.00169748370273794 -9.2816166883963517e-05 0 0 0</pose>
        <mass>0.76700000000000002</mass>
        <inertia>
          <ixx>0.00053999151781062584</ixx>
          <ixy>-2.1220993324641449e-06</ixy>
          <ixz>1.0653925501955671e-06</ixz>
          <iyy>0.00099813696478559337</iyy>
          <iyz>-1.4027352647979141e-06</iyz>
          <izz>0.00065828474786205991</izz>
        </inertia>
      </inertial>
      <collision name='FL_hip_collision'>
        <pose>0 0.095500000000000002 0 1.5707963267948959 0 0</pose>
        <geometry>
          <cylinder>
            <length>0.040000000000000001</length>
            <radius>0.045999999999999999</radius>
          </cylinder>
        </geometry>
        <surface>
          <contact>
            <ode/>
          </contact>
          <friction>
            <ode>
              <mu>0.20000000000000001</mu>
              <mu2>0.20000000000000001</mu2>
            </ode>
          </friction>
        </surface>
      </collision>
      <visual name='FL_hip_visual'>
        <pose>0 0 0 0 0 0</pose>
        <geometry>
          <mesh>
            <scale>1 1 1</scale>
            <uri>meshes/hip.dae</uri>
          </mesh>
        </geometry>
      </visual>
      <visual name='FL_hip_fixed_joint_lump__FL_thigh_rotor_visual_1'>
        <pose>0 -0.00014999999999999999 0 1.5707963267948959 0 0</pose>
        <geometry>
          <cylinder>
            <length>0.02</length>
            <radius>0.035000000000000003</radius>
          </cylinder>
        </geometry>
        <material>
          <diffuse>0 1 0 1</diffuse>
          <ambient>0 1 0 1</ambient>
        </material>
      </visual>
    </link>
    <joint name='FL_thigh_joint' type='revolute'>
      <pose relative_to='FL_hip'>0 0.095500000000000002 0 0 0 0</pose>
      <parent>FL_hip</parent>
      <child>FL_thigh</child>
      <axis>
        <xyz>0 1 0</xyz>
        <limit>
          <lower>-1.5708</lower>
          <upper>3.4906999999999999</upper>
          <effort>23.699999999999999</effort>
          <velocity>30.100000000000001</velocity>
        </limit>
        <dynamics>
          <damping>0</damping>
          <friction>0</friction>
          <spring_reference>0</spring_reference>
          <spring_stiffness>0</spring_stiffness>
        </dynamics>
      </axis>
    </joint>
    <link name='FL_thigh'>
      <pose relative_to='FL_thigh_joint'>0 0 0 0 0 0</pose>
      <inertial>
        <pose>-0.003471780821917808 -0.02302074939564867 -0.03035487510072523 0 0 0</pose>
        <mass>1.2410000000000001</mass>
        <inertia>
          <ixx>0.0059963333412087023</ixx>
          <ixy>9.0305334356164388e-05</ixy>
          <ixz>-0.00029910392372602731</ixz>
          <iyy>0.0060013394099700237</iyy>
          <iyz>0.00083515091803384382</iyz>
          <izz>0.0010991471651674461</izz>
        </inertia>
      </inertial>
      <collision name='FL_thigh_collision'>
        <pose>0 0 -0.1065 0 1.5707963267948966 0</pose>
        <geometry>
          <box>
            <size>0.21299999999999999 0.024500000000000001 0.034000000000000002</size>
          </box>
        </geometry>
        <surface>
          <contact>
            <ode>
              <kp>1000000</kp>
              <kd>1</kd>
            </ode>
          </contact>
          <friction>
            <ode>
              <mu>0.20000000000000001</mu>
              <mu2>0.20000000000000001</mu2>
            </ode>
          </friction>
        </surface>
      </collision>
      <visual name='FL_thigh_visual'>
        <pose>0 0 0 0 0 0</pose>
        <geometry>
          <mesh>
            <scale>1 1 1</scale>
            <uri>meshes/thigh.dae</uri>
          </mesh>
        </geometry>
      </visual>
      <visual name='FL_thigh_fixed_joint_lump__FL_calf_rotor_visual_1'>
        <pose>0 -0.032349999999999997 0 1.5707963267948959 0 0</pose>
        <geometry>
          <cylinder>
            <length>0.02</length>
            <radius>0.035000000000000003</radius>
          </cylinder>
        </geometry>
        <material>
          <diffuse>0 1 0 1</diffuse>
          <ambient>0 1 0 1</ambient>
        </material>
      </visual>
      <self_collide>true</self_collide>
    </link>
    <joint name='FL_calf_joint' type='revolute'>
      <pose relative_to='FL_thigh'>0 0 -0.21299999999999999 0 0 0</pose>
      <parent>FL_thigh</parent>
      <child>FL_calf</child>
      <axis>
        <xyz>0 1 0</xyz>
        <limit>
          <lower>-2.7227000000000001</lower>
          <upper>-0.83775999999999995</upper>
          <effort>35.549999999999997</effort>
          <velocity>20.059999999999999</velocity>
        </limit>
        <dynamics>
          <damping>0</damping>
          <friction>0</friction>
          <spring_reference>0</spring_reference>
          <spring_stiffness>0</spring_stiffness>
        </dynamics>
      </axis>
    </joint>
    <link name='FL_calf'>
      <pose relative_to='FL_calf_joint'>0 0 0 0 0 0</pose>
      <inertial>
        <pose>0.0039435514018691586 -0.00070163551401869158 -0.14247663551401871 0 0 0</pose>
        <mass>0.214</mass>
        <inertia>
          <ixx>0.001504318428855141</ixx>
          <ixy>5.7069775700934575e-07</ixy>
          <ixz>-5.9880822429906407e-06</ixz>
          <iyy>0.001525574022878506</iyy>
          <iyz>1.240561682242991e-05</iyz>
          <izz>4.3837685378504683e-05</izz>
        </inertia>
      </inertial>
      <collision name='FL_calf_collision'>
        <pose>0 0 -0.1065 0 1.5707963267948966 0</pose>
        <geometry>
          <box>
            <size>0.21299999999999999 0.016 0.016</size>
          </box>
        </geometry>
        <surface>
          <contact>
            <ode/>
          </contact>
          <friction>
            <ode>
              <mu>0.20000000000000001</mu>
              <mu2>0.20000000000000001</mu2>
            </ode>
          </friction>
        </surface>
      </collision>
      <collision name='FL_calf_fixed_joint_lump__FL_foot_collision_1'>
        <pose>0 0 -0.21299999999999999 0 0 0</pose>
        <geometry>
          <sphere>
            <radius>0.02</radius>
          </sphere>
        </geometry>
        <surface>
          <contact>
            <ode>
              <kp>1000000</kp>
              <kd>1</kd>
            </ode>
          </contact>
          <friction>
            <ode>
              <mu>0.59999999999999998</mu>
              <mu2>0.59999999999999998</mu2>
            </ode>
          </friction>
        </surface>
      </collision>
      <visual name='FL_calf_visual'>
        <pose>0 0 0 0 0 0</pose>
        <geometry>
          <mesh>
            <scale>1 1 1</scale>
            <uri>meshes/calf.dae</uri>
          </mesh>
        </geometry>
      </visual>
      <visual name='FL_calf_fixed_joint_lump__FL_foot_visual_1'>
        <pose>0 0 -0.21299999999999999 0 0 0</pose>
        <geometry>
          <sphere>
            <radius>0.01</radius>
          </sphere>
        </geometry>
      </visual>
      <sensor name='FL_foot_contact' type='contact'>
        <update_rate>100</update_rate>
        <contact>
          <collision>FL_calf_fixed_joint_lump__FL_foot_collision_1</collision>
          <topic>/FL_foot_contact</topic>
        </contact>
      </sensor>
      <self_collide>true</self_collide>
      <self_collide>true</self_collide>
    </link>
    <joint name='FR_hip_joint' type='revolute'>
      <pose relative_to='base'>0.19339999999999999 -0.0465 0 0 0 0</pose>
      <parent>base</parent>
      <child>FR_hip</child>
      <axis>
        <xyz>1 0 0</xyz>
        <limit>
          <lower>-1.0471999999999999</lower>
          <upper>1.0471999999999999</upper>
          <effort>23.699999999999999</effort>
          <velocity>30.100000000000001</velocity>
        </limit>
        <dynamics>
          <damping>0</damping>
          <friction>0</friction>
          <spring_reference>0</spring_reference>
          <spring_stiffness>0</spring_stiffness>
        </dynamics>
      </axis>
    </joint>
    <link name='FR_hip'>
      <pose relative_to='FR_hip_joint'>0 0 0 0 0 0</pose>
      <inertial>
        <pose>-0.0047734028683181226 -0.00169748370273794 -9.2816166883963517e-05 0 0 0</pose>
        <mass>0.76700000000000002</mass>
        <inertia>
          <ixx>0.00053999151781062584</ixx>
          <ixy>2.1220993324641449e-06</ixy>
          <ixz>1.0653925501955671e-06</ixz>
          <iyy>0.00099813696478559337</iyy>
          <iyz>1.4027352647979141e-06</iyz>
          <izz>0.00065828474786205991</izz>
        </inertia>
      </inertial>
      <collision name='FR_hip_collision'>
        <pose>0 -0.095500000000000002 0 1.5707963267948959 0 0</pose>
        <geometry>
          <cylinder>
            <length>0.040000000000000001</length>
            <radius>0.045999999999999999</radius>
          </cylinder>
        </geometry>
        <surface>
          <contact>
            <ode/>
          </contact>
          <friction>
            <ode>
              <mu>0.20000000000000001</mu>
              <mu2>0.20000000000000001</mu2>
            </ode>
          </friction>
        </surface>
      </collision>
      <visual name='FR_hip_visual'>
        <pose>0 0 0 3.1415926535897931 0 0</pose>
        <geometry>
          <mesh>
            <scale>1 1 1</scale>
            <uri>meshes/hip.dae</uri>
          </mesh>
        </geometry>
      </visual>
      <visual name='FR_hip_fixed_joint_lump__FR_thigh_rotor_visual_1'>
        <pose>0 0.00014999999999999999 0 1.5707963267948959 0 0</pose>
        <geometry>
          <cylinder>
            <length>0.02</length>
            <radius>0.035000000000000003</radius>
          </cylinder>
        </geometry>
        <material>
          <diffuse>0 1 0 1</diffuse>
          <ambient>0 1 0 1</ambient>
        </material>
      </visual>
    </link>
    <joint name='FR_thigh_joint' type='revolute'>
      <pose relative_to='FR_hip'>0 -0.095500000000000002 0 0 0 0</pose>
      <parent>FR_hip</parent>
      <child>FR_thigh</child>
      <axis>
        <xyz>0 1 0</xyz>
        <limit>
          <lower>-1.5708</lower>
          <upper>3.4906999999999999</upper>
          <effort>23.699999999999999</effort>
          <velocity>30.100000000000001</velocity>
        </limit>
        <dynamics>
          <damping>0</damping>
          <friction>0</friction>
          <spring_reference>0</spring_reference>
          <spring_stiffness>0</spring_stiffness>
        </dynamics>
      </axis>
    </joint>
    <link name='FR_thigh'>
      <pose relative_to='FR_thigh_joint'>0 0 0 0 0 0</pose>
      <inertial>
        <pose>-0.003471780821917808 0.02302074939564867 -0.03035487510072523 0 0 0</pose>
        <mass>1.2410000000000001</mass>
        <inertia>
          <ixx>0.0059963333412087023</ixx>
          <ixy>-9.0305334356164388e-05</ixy>
          <ixz>-0.00029910392372602731</ixz>
          <iyy>0.0060013394099700237</iyy>
          <iyz>-0.00083515091803384382</iyz>
          <izz>0.0010991471651674461</izz>
        </inertia>
      </inertial>
      <collision name='FR_thigh_collision'>
        <pose>0 0 -0.1065 0 1.5707963267948966 0</pose>
        <geometry>
          <box>
            <size>0.21299999999999999 0.024500000000000001 0.034000000000000002</size>
          </box>
        </geometry>
        <surface>
          <contact>
            <ode>
              <kp>1000000</kp>
              <kd>1</kd>
            </ode>
          </contact>
          <friction>
            <ode>
              <mu>0.20000000000000001</mu>
              <mu2>0.20000000000000001</mu2>
            </ode>
          </friction>
        </surface>
      </collision>
      <visual name='FR_thigh_visual'>
        <pose>0 0 0 0 0 0</pose>
        <geometry>
          <mesh>
            <scale>1 1 1</scale>
            <uri>meshes/thigh_mirror.dae</uri>
          </mesh>
        </geometry>
      </visual>
      <visual name='FR_thigh_fixed_joint_lump__FR_calf_rotor_visual_1'>
        <pose>0 0.032349999999999997 0 1.5707963267948959 0 0</pose>
        <geometry>
          <cylinder>
            <length>0.02</length>
            <radius>0.035000000000000003</radius>
          </cylinder>
        </geometry>
        <material>
          <diffuse>0 1 0 1</diffuse>
          <ambient>0 1 0 1</ambient>
        </material>
      </visual>
      <self_collide>true</self_collide>
    </link>
    <joint name='FR_calf_joint' type='revolute'>
      <pose relative_to='FR_thigh'>0 0 -0.21299999999999999 0 0 0</pose>
      <parent>FR_thigh</parent>
      <child>FR_calf</child>
      <axis>
        <xyz>0 1 0</xyz>
        <limit>
          <lower>-2.7227000000000001</lower>
          <upper>-0.83775999999999995</upper>
          <effort>35.549999999999997</effort>
          <velocity>20.059999999999999</velocity>
        </limit>
        <dynamics>
          <damping>0</damping>
          <friction>0</friction>
          <spring_reference>0</spring_reference>
          <spring_stiffness>0</spring_stiffness>
        </dynamics>
      </axis>
    </joint>
    <link name='FR_calf'>
      <pose relative_to='FR_calf_joint'>0 0 0 0 0 0</pose>
      <inertial>
        <pose>0.0039435514018691586 -0.00070163551401869158 -0.14247663551401871 0 0 0</pose>
        <mass>0.214</mass>
        <inertia>
          <ixx>0.001504318428855141</ixx>
          <ixy>5.7069775700934575e-07</ixy>
          <ixz>-5.9880822429906407e-06</ixz>
          <iyy>0.001525574022878506</iyy>
          <iyz>1.240561682242991e-05</iyz>
          <izz>4.3837685378504683e-05</izz>
        </inertia>
      </inertial>
      <collision name='FR_calf_collision'>
        <pose>0 0 -0.1065 0 1.5707963267948966 0</pose>
        <geometry>
          <box>
            <size>0.21299999999999999 0.016 0.016</size>
          </box>
        </geometry>
        <surface>
          <contact>
            <ode/>
          </contact>
          <friction>
            <ode>
              <mu>0.20000000000000001</mu>
              <mu2>0.20000000000000001</mu2>
            </ode>
          </friction>
        </surface>
      </collision>
      <collision name='FR_calf_fixed_joint_lump__FR_foot_collision_1'>
        <pose>0 0 -0.21299999999999999 0 0 0</pose>
        <geometry>
          <sphere>
            <radius>0.02</radius>
          </sphere>
        </geometry>
        <surface>
          <contact>
            <ode>
              <kp>1000000</kp>
              <kd>1</kd>
            </ode>
          </contact>
          <friction>
            <ode>
              <mu>0.59999999999999998</mu>
              <mu2>0.59999999999999998</mu2>
            </ode>
          </friction>
        </surface>
      </collision>
      <visual name='FR_calf_visual'>
        <pose>0 0 0 0 0 0</pose>
        <geometry>
          <mesh>
            <scale>1 1 1</scale>
            <uri>meshes/calf.dae</uri>
          </mesh>
        </geometry>
      </visual>
      <visual name='FR_calf_fixed_joint_lump__FR_foot_visual_1'>
        <pose>0 0 -0.21299999999999999 0 0 0</pose>
        <geometry>
          <sphere>
            <radius>0.01</radius>
          </sphere>
        </geometry>
      </visual>
      <sensor name='FR_foot_contact' type='contact'>
        <update_rate>100</update_rate>
        <contact>
          <collision>FR_calf_fixed_joint_lump__FR_foot_collision_1</collision>
          <topic>/FR_foot_contact</topic>
        </contact>
      </sensor>
      <self_collide>true</self_collide>
      <self_collide>true</self_collide>
    </link>
    <joint name='RL_hip_joint' type='revolute'>
      <pose relative_to='base'>-0.19339999999999999 0.0465 0 0 0 0</pose>
      <parent>base</parent>
      <child>RL_hip</child>
      <axis>
        <xyz>1 0 0</xyz>
        <limit>
          <lower>-1.0471999999999999</lower>
          <upper>1.0471999999999999</upper>
          <effort>23.699999999999999</effort>
          <velocity>30.100000000000001</velocity>
        </limit>
        <dynamics>
          <damping>0</damping>
          <friction>0</friction>
          <spring_reference>0</spring_reference>
          <spring_stiffness>0</spring_stiffness>
        </dynamics>
      </axis>
    </joint>
    <link name='RL_hip'>
      <pose relative_to='RL_hip_joint'>0 0 0 0 0 0</pose>
      <inertial>
        <pose>0.0047734028683181226 0.00169748370273794 -9.2816166883963517e-05 0 0 0</pose>
        <mass>0.76700000000000002</mass>
        <inertia>
          <ixx>0.00053999151781062584</ixx>
          <ixy>2.1220993324641449e-06</ixy>
          <ixz>-1.0653925501955671e-06</ixz>
          <iyy>0.00099813696478559337</iyy>
          <iyz>-1.4027352647979141e-06</iyz>
          <izz>0.00065828474786205991</izz>
        </inertia>
      </inertial>
      <collision name='RL_hip_collision'>
        <pose>0 0.095500000000000002 0 1.5707963267948959 0 0</pose>
        <geometry>
          <cylinder>
            <length>0.040000000000000001</length>
            <radius>0.045999999999999999</radius>
          </cylinder>
        </geometry>
        <surface>
          <contact>
            <ode/>
          </contact>
          <friction>
            <ode>
              <mu>0.20000000000000001</mu>
              <mu2>0.20000000000000001</mu2>
            </ode>
          </friction>
        </surface>
      </collision>
      <visual name='RL_hip_visual'>
        <pose>0 0 0 3.1415926535897931 1.224646799147353e-16 3.1415926535897931</pose>
        <geometry>
          <mesh>
            <scale>1 1 1</scale>
            <uri>meshes/hip.dae</uri>
          </mesh>
        </geometry>
      </visual>
      <visual name='RL_hip_fixed_joint_lump__RL_thigh_rotor_visual_1'>
        <pose>0 -0.00014999999999999999 0 1.5707963267948959 0 0</pose>
        <geometry>
          <cylinder>
            <length>0.02</length>
            <radius>0.035000000000000003</radius>
          </cylinder>
        </geometry>
        <material>
          <diffuse>0 1 0 1</diffuse>
          <ambient>0 1 0 1</ambient>
        </material>
      </visual>
    </link>
    <joint name='RL_thigh_joint' type='revolute'>
      <pose relative_to='RL_hip'>0 0.095500000000000002 0 0 0 0</pose>
      <parent>RL_hip</parent>
      <child>RL_thigh</child>
      <axis>
        <xyz>0 1 0</xyz>
        <limit>
          <lower>-1.5708</lower>
          <upper>3.4906999999999999</upper>
          <effort>23.699999999999999</effort>
          <velocity>30.100000000000001</velocity>
        </limit>
        <dynamics>
          <damping>0</damping>
          <friction>0</friction>
          <spring_reference>0</spring_reference>
          <spring_stiffness>0</spring_stiffness>
        </dynamics>
      </axis>
    </joint>
    <link name='RL_thigh'>
      <pose relative_to='RL_thigh_joint'>0 0 0 0 0 0</pose>
      <inertial>
        <pose>-0.003471780821917808 -0.02302074939564867 -0.03035487510072523 0 0 0</pose>
        <mass>1.2410000000000001</mass>
        <inertia>
          <ixx>0.0059963333412087023</ixx>
          <ixy>9.0305334356164388e-05</ixy>
          <ixz>-0.00029910392372602731</ixz>
          <iyy>0.0060013394099700237</iyy>
          <iyz>0.00083515091803384382</iyz>
          <izz>0.0010991471651674461</izz>
        </inertia>
      </inertial>
      <collision name='RL_thigh_collision'>
        <pose>0 0 -0.1065 0 1.5707963267948966 0</pose>
        <geometry>
          <box>
            <size>0.21299999999999999 0.024500000000000001 0.034000000000000002</size>
          </box>
        </geometry>
        <surface>
          <contact>
            <ode>
              <kp>1000000</kp>
              <kd>1</kd>
            </ode>
          </contact>
          <friction>
            <ode>
              <mu>0.20000000000000001</mu>
              <mu2>0.20000000000000001</mu2>
            </ode>
          </friction>
        </surface>
      </collision>
      <visual name='RL_thigh_visual'>
        <pose>0 0 0 0 0 0</pose>
        <geometry>
          <mesh>
            <scale>1 1 1</scale>
            <uri>meshes/thigh.dae</uri>
          </mesh>
        </geometry>
      </visual>
      <visual name='RL_thigh_fixed_joint_lump__RL_calf_rotor_visual_1'>
        <pose>0 -0.032349999999999997 0 1.5707963267948959 0 0</pose>
        <geometry>
          <cylinder>
            <length>0.02</length>
            <radius>0.035000000000000003</radius>
          </cylinder>
        </geometry>
        <material>
          <diffuse>0 1 0 1</diffuse>
          <ambient>0 1 0 1</ambient>
        </material>
      </visual>
      <self_collide>true</self_collide>
    </link>
    <joint name='RL_calf_joint' type='revolute'>
      <pose relative_to='RL_thigh'>0 0 -0.21299999999999999 0 0 0</pose>
      <parent>RL_thigh</parent>
      <child>RL_calf</child>
      <axis>
        <xyz>0 1 0</xyz>
        <limit>
          <lower>-2.7227000000000001</lower>
          <upper>-0.83775999999999995</upper>
          <effort>35.549999999999997</effort>
          <velocity>20.059999999999999</velocity>
        </limit>
        <dynamics>
          <damping>0</damping>
          <friction>0</friction>
          <spring_reference>0</spring_reference>
          <spring_stiffness>0</spring_stiffness>
        </dynamics>
      </axis>
    </joint>
    <link name='RL_calf'>
      <pose relative_to='RL_calf_joint'>0 0 0 0 0 0</pose>
      <inertial>
        <pose>0.0039435514018691586 -0.00070163551401869158 -0.14247663551401871 0 0 0</pose>
        <mass>0.214</mass>
        <inertia>
          <ixx>0.001504318428855141</ixx>
          <ixy>5.7069775700934575e-07</ixy>
          <ixz>-5.9880822429906407e-06</ixz>
          <iyy>0.001525574022878506</iyy>
          <iyz>1.240561682242991e-05</iyz>
          <izz>4.3837685378504683e-05</izz>
        </inertia>
      </inertial>
      <collision name='RL_calf_collision'>
        <pose>0 0 -0.1065 0 1.5707963267948966 0</pose>
        <geometry>
          <box>
            <size>0.21299999999999999 0.016 0.016</size>
          </box>
        </geometry>
        <surface>
          <contact>
            <ode/>
          </contact>
          <friction>
            <ode>
              <mu>0.20000000000000001</mu>
              <mu2>0.20000000000000001</mu2>
            </ode>
          </friction>
        </surface>
      </collision>
      <collision name='RL_calf_fixed_joint_lump__RL_foot_collision_1'>
        <pose>0 0 -0.21299999999999999 0 0 0</pose>
        <geometry>
          <sphere>
            <radius>0.02</radius>
          </sphere>
        </geometry>
        <surface>
          <contact>
            <ode>
              <kp>1000000</kp>
              <kd>1</kd>
            </ode>
          </contact>
          <friction>
            <ode>
              <mu>0.59999999999999998</mu>
              <mu2>0.59999999999999998</mu2>
            </ode>
          </friction>
        </surface>
      </collision>
      <visual name='RL_calf_visual'>
        <pose>0 0 0 0 0 0</pose>
        <geometry>
          <mesh>
            <scale>1 1 1</scale>
            <uri>meshes/calf.dae</uri>
          </mesh>
        </geometry>
      </visual>
      <visual name='RL_calf_fixed_joint_lump__RL_foot_visual_1'>
        <pose>0 0 -0.21299999999999999 0 0 0</pose>
        <geometry>
          <sphere>
            <radius>0.01</radius>
          </sphere>
        </geometry>
      </visual>
      <sensor name='RL_foot_contact' type='contact'>
        <update_rate>100</update_rate>
        <contact>
          <collision>RL_calf_fixed_joint_lump__RL_foot_collision_1</collision>
          <topic>/RL_foot_contact</topic>
        </contact>
      </sensor>
      <self_collide>true</self_collide>
      <self_collide>true</self_collide>
    </link>
    <joint name='RR_hip_joint' type='revolute'>
      <pose relative_to='base'>-0.19339999999999999 -0.0465 0 0 0 0</pose>
      <parent>base</parent>
      <child>RR_hip</child>
      <axis>
        <xyz>1 0 0</xyz>
        <limit>
          <lower>-1.0471999999999999</lower>
          <upper>1.0471999999999999</upper>
          <effort>23.699999999999999</effort>
          <velocity>30.100000000000001</velocity>
        </limit>
        <dynamics>
          <damping>0</damping>
          <friction>0</friction>
          <spring_reference>0</spring_reference>
          <spring_stiffness>0</spring_stiffness>
        </dynamics>
      </axis>
    </joint>
    <link name='RR_hip'>
      <pose relative_to='RR_hip_joint'>0 0 0 0 0 0</pose>
      <inertial>
        <pose>0.0047734028683181226 -0.00169748370273794 -9.2816166883963517e-05 0 0 0</pose>
        <mass>0.76700000000000002</mass>
        <inertia>
          <ixx>0.00053999151781062584</ixx>
          <ixy>-2.1220993324641449e-06</ixy>
          <ixz>-1.0653925501955671e-06</ixz>
          <iyy>0.00099813696478559337</iyy>
          <iyz>1.4027352647979141e-06</iyz>
          <izz>0.00065828474786205991</izz>
        </inertia>
      </inertial>
      <collision name='RR_hip_collision'>
        <pose>0 -0.095500000000000002 0 1.5707963267948959 0 0</pose>
        <geometry>
          <cylinder>
            <length>0.040000000000000001</length>
            <radius>0.045999999999999999</radius>
          </cylinder>
        </geometry>
        <surface>
          <contact>
            <ode/>
          </contact>
          <friction>
            <ode>
              <mu>0.20000000000000001</mu>
              <mu2>0.20000000000000001</mu2>
            </ode>
          </friction>
        </surface>
      </collision>
      <visual name='RR_hip_visual'>
        <pose>0 0 0 -1.224646799147353e-16 1.224646799147353e-16 3.1415926535897931</pose>
        <geometry>
          <mesh>
            <scale>1 1 1</scale>
            <uri>meshes/hip.dae</uri>
          </mesh>
        </geometry>
      </visual>
      <visual name='RR_hip_fixed_joint_lump__RR_thigh_rotor_visual_1'>
        <pose>0 0.00014999999999999999 0 1.5707963267948959 0 0</pose>
        <geometry>
          <cylinder>
            <length>0.02</length>
            <radius>0.035000000000000003</radius>
          </cylinder>
        </geometry>
        <material>
          <diffuse>0 1 0 1</diffuse>
          <ambient>0 1 0 1</ambient>
        </material>
      </visual>
    </link>
    <joint name='RR_thigh_joint' type='revolute'>
      <pose relative_to='RR_hip'>0 -0.095500000000000002 0 0 0 0</pose>
      <parent>RR_hip</parent>
      <child>RR_thigh</child>
      <axis>
        <xyz>0 1 0</xyz>
        <limit>
          <lower>-1.5708</lower>
          <upper>3.4906999999999999</upper>
          <effort>23.699999999999999</effort>
          <velocity>30.100000000000001</velocity>
        </limit>
        <dynamics>
          <damping>0</damping>
          <friction>0</friction>
          <spring_reference>0</spring_reference>
          <spring_stiffness>0</spring_stiffness>
        </dynamics>
      </axis>
    </joint>
    <link name='RR_thigh'>
      <pose relative_to='RR_thigh_joint'>0 0 0 0 0 0</pose>
      <inertial>
        <pose>-0.003471780821917808 0.02302074939564867 -0.03035487510072523 0 0 0</pose>
        <mass>1.2410000000000001</mass>
        <inertia>
          <ixx>0.0059963333412087023</ixx>
          <ixy>-9.0305334356164388e-05</ixy>
          <ixz>-0.00029910392372602731</ixz>
          <iyy>0.0060013394099700237</iyy>
          <iyz>-0.00083515091803384382</iyz>
          <izz>0.0010991471651674461</izz>
        </inertia>
      </inertial>
      <collision name='RR_thigh_collision'>
        <pose>0 0 -0.1065 0 1.5707963267948966 0</pose>
        <geometry>
          <box>
            <size>0.21299999999999999 0.024500000000000001 0.034000000000000002</size>
          </box>
        </geometry>
        <surface>
          <contact>
            <ode>
              <kp>1000000</kp>
              <kd>1</kd>
            </ode>
          </contact>
          <friction>
            <ode>
              <mu>0.20000000000000001</mu>
              <mu2>0.20000000000000001</mu2>
            </ode>
          </friction>
        </surface>
      </collision>
      <visual name='RR_thigh_visual'>
        <pose>0 0 0 0 0 0</pose>
        <geometry>
          <mesh>
            <scale>1 1 1</scale>
            <uri>meshes/thigh_mirror.dae</uri>
          </mesh>
        </geometry>
      </visual>
      <visual name='RR_thigh_fixed_joint_lump__RR_calf_rotor_visual_1'>
        <pose>0 0.032349999999999997 0 1.5707963267948959 0 0</pose>
        <geometry>
          <cylinder>
            <length>0.02</length>
            <radius>0.035000000000000003</radius>
          </cylinder>
        </geometry>
        <material>
          <diffuse>0 1 0 1</diffuse>
          <ambient>0 1 0 1</ambient>
        </material>
      </visual>
      <self_collide>true</self_collide>
    </link>
    <joint name='RR_calf_joint' type='revolute'>
      <pose relative_to='RR_thigh'>0 0 -0.21299999999999999 0 0 0</pose>
      <parent>RR_thigh</parent>
      <child>RR_calf</child>
      <axis>
        <xyz>0 1 0</xyz>
        <limit>
          <lower>-2.7227000000000001</lower>
          <upper>-0.83775999999999995</upper>
          <effort>35.549999999999997</effort>
          <velocity>20.059999999999999</velocity>
        </limit>
        <dynamics>
          <damping>0</damping>
          <friction>0</friction>
          <spring_reference>0</spring_reference>
          <spring_stiffness>0</spring_stiffness>
        </dynamics>
      </axis>
    </joint>
    <link name='RR_calf'>
      <pose relative_to='RR_calf_joint'>0 0 0 0 0 0</pose>
      <inertial>
        <pose>0.0039435514018691586 -0.00070163551401869158 -0.14247663551401871 0 0 0</pose>
        <mass>0.214</mass>
        <inertia>
          <ixx>0.001504318428855141</ixx>
          <ixy>5.7069775700934575e-07</ixy>
          <ixz>-5.9880822429906407e-06</ixz>
          <iyy>0.001525574022878506</iyy>
          <iyz>1.240561682242991e-05</iyz>
          <izz>4.3837685378504683e-05</izz>
        </inertia>
      </inertial>
      <collision name='RR_calf_collision'>
        <pose>0 0 -0.1065 0 1.5707963267948966 0</pose>
        <geometry>
          <box>
            <size>0.21299999999999999 0.016 0.016</size>
          </box>
        </geometry>
        <surface>
          <contact>
            <ode/>
          </contact>
          <friction>
            <ode>
              <mu>0.20000000000000001</mu>
              <mu2>0.20000000000000001</mu2>
            </ode>
          </friction>
        </surface>
      </collision>
      <collision name='RR_calf_fixed_joint_lump__RR_foot_collision_1'>
        <pose>0 0 -0.21299999999999999 0 0 0</pose>
        <geometry>
          <sphere>
            <radius>0.02</radius>
          </sphere>
        </geometry>
        <surface>
          <contact>
            <ode>
              <kp>1000000</kp>
              <kd>1</kd>
            </ode>
          </contact>
          <friction>
            <ode>
              <mu>0.59999999999999998</mu>
              <mu2>0.59999999999999998</mu2>
            </ode>
          </friction>
        </surface>
      </collision>
      <visual name='RR_calf_visual'>
        <pose>0 0 0 0 0 0</pose>
        <geometry>
          <mesh>
            <scale>1 1 1</scale>
            <uri>meshes/calf.dae</uri>
          </mesh>
        </geometry>
      </visual>
      <visual name='RR_calf_fixed_joint_lump__RR_foot_visual_1'>
        <pose>0 0 -0.21299999999999999 0 0 0</pose>
        <geometry>
          <sphere>
            <radius>0.01</radius>
          </sphere>
        </geometry>
      </visual>
      <sensor name='RR_foot_contact' type='contact'>
        <update_rate>100</update_rate>
        <contact>
          <collision>RR_calf_fixed_joint_lump__RR_foot_collision_1</collision>
          <topic>/RR_foot_contact</topic>
        </contact>
      </sensor>
      <self_collide>true</self_collide>
      <self_collide>true</self_collide>
    </link>

    <!-- Gazebo Sim plugins -->

    <!-- Joint State Publisher: publishes joint states -->
    <plugin filename="gz-sim-joint-state-publisher-system"
            name="gz::sim::systems::JointStatePublisher">
      <topic>/go2/joint_states</topic>
    </plugin>

    <!-- Apply Joint Force: one plugin instance per joint -->
    <plugin filename="gz-sim-apply-joint-force-system" name="gz::sim::systems::ApplyJointForce">
      <joint_name>FL_hip_joint</joint_name>
    </plugin>
    <plugin filename="gz-sim-apply-joint-force-system" name="gz::sim::systems::ApplyJointForce">
      <joint_name>FL_thigh_joint</joint_name>
    </plugin>
    <plugin filename="gz-sim-apply-joint-force-system" name="gz::sim::systems::ApplyJointForce">
      <joint_name>FL_calf_joint</joint_name>
    </plugin>
    <plugin filename="gz-sim-apply-joint-force-system" name="gz::sim::systems::ApplyJointForce">
      <joint_name>FR_hip_joint</joint_name>
    </plugin>
    <plugin filename="gz-sim-apply-joint-force-system" name="gz::sim::systems::ApplyJointForce">
      <joint_name>FR_thigh_joint</joint_name>
    </plugin>
    <plugin filename="gz-sim-apply-joint-force-system" name="gz::sim::systems::ApplyJointForce">
      <joint_name>FR_calf_joint</joint_name>
    </plugin>
    <plugin filename="gz-sim-apply-joint-force-system" name="gz::sim::systems::ApplyJointForce">
      <joint_name>RL_hip_joint</joint_name>
    </plugin>
    <plugin filename="gz-sim-apply-joint-force-system" name="gz::sim::systems::ApplyJointForce">
      <joint_name>RL_thigh_joint</joint_name>
    </plugin>
    <plugin filename="gz-sim-apply-joint-force-system" name="gz::sim::systems::ApplyJointForce">
      <joint_name>RL_calf_joint</joint_name>
    </plugin>
    <plugin filename="gz-sim-apply-joint-force-system" name="gz::sim::systems::ApplyJointForce">
      <joint_name>RR_hip_joint</joint_name>
    </plugin>
    <plugin filename="gz-sim-apply-joint-force-system" name="gz::sim::systems::ApplyJointForce">
      <joint_name>RR_thigh_joint</joint_name>
    </plugin>
    <plugin filename="gz-sim-apply-joint-force-system" name="gz::sim::systems::ApplyJointForce">
      <joint_name>RR_calf_joint</joint_name>
    </plugin>

    <!-- Apply link wrench for external forces (optional) -->
    <!-- <plugin filename='gz-sim-apply-link-wrench-system'
            name='gz::sim::systems::ApplyLinkWrench'>
      <link_name>base</link_name>
    </plugin> -->

    <frame name='FL_hip_rotor_joint' attached_to='trunk'>
      <pose>0.11215 0.04675 0 0 0 0</pose>
    </frame>
    <frame name='FL_hip_rotor' attached_to='FL_hip_rotor_joint'>
      <pose>0 0 0 0 0 0</pose>
    </frame>
    <frame name='FR_hip_rotor_joint' attached_to='trunk'>
      <pose>0.11215 -0.04675 0 0 0 0</pose>
    </frame>
    <frame name='FR_hip_rotor' attached_to='FR_hip_rotor_joint'>
      <pose>0 0 0 0 0 0</pose>
    </frame>
    <frame name='RL_hip_rotor_joint' attached_to='trunk'>
      <pose>-0.11215 0.04675 0 0 0 0</pose>
    </frame>
    <frame name='RL_hip_rotor' attached_to='RL_hip_rotor_joint'>
      <pose>0 0 0 0 0 0</pose>
    </frame>
    <frame name='RR_hip_rotor_joint' attached_to='trunk'>
      <pose>-0.11215 -0.04675 0 0 0 0</pose>
    </frame>
    <frame name='RR_hip_rotor' attached_to='RR_hip_rotor_joint'>
      <pose>0 0 0 0 0 0</pose>
    </frame>
    <frame name='front_camera_joint' attached_to='trunk'>
      <pose>0.32715 -3.0000000000000001e-05 0.042970000000000001 0 0 0</pose>
    </frame>
    <frame name='front_camera' attached_to='front_camera_joint'>
      <pose>0 0 0 0 0 0</pose>
    </frame>
    <frame name='imu_joint' attached_to='trunk'>
      <pose>0 0 0 0 0 0</pose>
    </frame>
    <frame name='imu_link' attached_to='imu_joint'>
      <pose>0 0 0 0 0 0</pose>
    </frame>
    <frame name='floating_base' attached_to='base'>
      <pose>0 0 0 0 0 0</pose>
    </frame>
    <frame name='trunk' attached_to='floating_base'>
      <pose>0 0 0 0 0 0</pose>
    </frame>
    <frame name='FL_thigh_rotor_joint' attached_to='FL_hip'>
      <pose>0 -0.00014999999999999999 0 0 0 0</pose>
    </frame>
    <frame name='FL_thigh_rotor' attached_to='FL_thigh_rotor_joint'>
      <pose>0 0 0 0 0 0</pose>
    </frame>
    <frame name='FL_calf_rotor_joint' attached_to='FL_thigh'>
      <pose>0 -0.032349999999999997 0 0 0 0</pose>
    </frame>
    <frame name='FL_calf_rotor' attached_to='FL_calf_rotor_joint'>
      <pose>0 0 0 0 0 0</pose>
    </frame>
    <frame name='FL_foot_fixed' attached_to='FL_calf'>
      <pose>0 0 -0.21299999999999999 0 0 0</pose>
    </frame>
    <frame name='FL_foot' attached_to='FL_foot_fixed'>
      <pose>0 0 0 0 0 0</pose>
    </frame>
    <frame name='FR_thigh_rotor_joint' attached_to='FR_hip'>
      <pose>0 0.00014999999999999999 0 0 0 0</pose>
    </frame>
    <frame name='FR_thigh_rotor' attached_to='FR_thigh_rotor_joint'>
      <pose>0 0 0 0 0 0</pose>
    </frame>
    <frame name='FR_calf_rotor_joint' attached_to='FR_thigh'>
      <pose>0 0.032349999999999997 0 0 0 0</pose>
    </frame>
    <frame name='FR_calf_rotor' attached_to='FR_calf_rotor_joint'>
      <pose>0 0 0 0 0 0</pose>
    </frame>
    <frame name='FR_foot_fixed' attached_to='FR_calf'>
      <pose>0 0 -0.21299999999999999 0 0 0</pose>
    </frame>
    <frame name='FR_foot' attached_to='FR_foot_fixed'>
      <pose>0 0 0 0 0 0</pose>
    </frame>
    <frame name='RL_thigh_rotor_joint' attached_to='RL_hip'>
      <pose>0 -0.00014999999999999999 0 0 0 0</pose>
    </frame>
    <frame name='RL_thigh_rotor' attached_to='RL_thigh_rotor_joint'>
      <pose>0 0 0 0 0 0</pose>
    </frame>
    <frame name='RL_calf_rotor_joint' attached_to='RL_thigh'>
      <pose>0 -0.032349999999999997 0 0 0 0</pose>
    </frame>
    <frame name='RL_calf_rotor' attached_to='RL_calf_rotor_joint'>
      <pose>0 0 0 0 0 0</pose>
    </frame>
    <frame name='RL_foot_fixed' attached_to='RL_calf'>
      <pose>0 0 -0.21299999999999999 0 0 0</pose>
    </frame>
    <frame name='RL_foot' attached_to='RL_foot_fixed'>
      <pose>0 0 0 0 0 0</pose>
    </frame>
    <frame name='RR_thigh_rotor_joint' attached_to='RR_hip'>
      <pose>0 0.00014999999999999999 0 0 0 0</pose>
    </frame>
    <frame name='RR_thigh_rotor' attached_to='RR_thigh_rotor_joint'>
      <pose>0 0 0 0 0 0</pose>
    </frame>
    <frame name='RR_calf_rotor_joint' attached_to='RR_thigh'>
      <pose>0 0.032349999999999997 0 0 0 0</pose>
    </frame>
    <frame name='RR_calf_rotor' attached_to='RR_calf_rotor_joint'>
      <pose>0 0 0 0 0 0</pose>
    </frame>
    <frame name='RR_foot_fixed' attached_to='RR_calf'>
      <pose>0 0 -0.21299999999999999 0 0 0</pose>
    </frame>
    <frame name='RR_foot' attached_to='RR_foot_fixed'>
      <pose>0 0 0 0 0 0</pose>
    </frame>
  </model>
</sdf>
